Workbook

Sheet Contract
F1: Indian Institute of Petroleum and Energy
A3: Salary Statement of Contract Staff - Non Teaching for the month of August'26
A4: S.No. | B4: Name of the Employee | C4: Designation | D4: Monthly Salary | E4: No.of Days Salary Payable | F4: Gross Salary | G4: PT | H4: TDS | I4: PF | J4: Other deductions | K4: Total Deductions | L4: Net Salary | M4: Contract Period
A5: 1 | B5: Mr.U.Rajesh Kumar | C5: Office Asst. | D5: 26700 | E5: 31 | F5: =D5/31*E5 -> 26700 | G5: 200 | H5: 0 | I5: 1800 | J5: 0 | K5: =+SUM(G5:J5) -> 2000 | L5: =ROUND(F5-K5,0) -> 24700 | M5: 15.09.2025 to 14.09.2026
A6: 2 | B6: Mr.P.Lakshman Krishna | C6: Office Asst. | D6: 28000 | E6: 31 | F6: =D6/31*E6 -> 28000 | G6: 200 | H6: 0 | I6: 1800 | J6: 0 | K6: =+SUM(G6:J6) -> 2000 | L6: =ROUND(F6-K6,0) -> 26000 | M6: 09.05.2025 to 08.04.2026 & 10.04.2026 to 09.04.2027
A7: 3 | B7: Mr.K.Govinda Rao | C7: Office Asst. | D7: 28000 | E7: 31 | F7: =D7/31*E7 -> 28000 | G7: 200 | H7: 0 | I7: =15000*12/100 -> 1800 | J7: 0 | K7: =+SUM(G7:J7) -> 2000 | L7: =ROUND(F7-K7,0) -> 26000 | M7: 08.06.2025 to 07.05.2026 & 09.05.2026 to 08.05.2027
A8: 4 | B8: Mr. K Hari Gopala Rao | C8: Junior Assistant | D8: 39500 | E8: 31 | F8: =D8/31*E8 -> 39500 | G8: 200 | H8: 0 | I8: =15000*12/100 -> 1800 | J8: 0 | K8: =+SUM(G8:J8) -> 2000 | L8: =ROUND(F8-K8,0) -> 37500 | M8: 08.06.2025 to 07.05.2026 &09.05.2026 to 08.05.2027
A9: 5 | B9: G.Venkateswara Rao | C9: Sports Officer | D9: 52100 | E9: 31 | F9: =D9/31*E9 -> 52100 | G9: 200 | H9: 0 | I9: 0 | J9: 0 | K9: =+SUM(G9:J9) -> 200 | L9: =ROUND(F9-K9,0) -> 51900 | M9: 06.10.2025 to 05.10.2026
A10: 6 | B10: V V Sateesh Kumar Annepu | C10: Placement officer | D10: 90700 | E10: 29 | F10: =D10/31*E10 -> 84848.387 | G10: 200 | H10: 0 | I10: 0 | J10: 0 | K10: =+SUM(G10:J10) -> 200 | L10: =ROUND(F10-K10,0) -> 84648 | M10: 02.06.2025 to 01.05.2026 & 02.05.2026 to 31.07.2026
A11: Total | D11: =+SUM(D5:D10) -> 265000 | F11: =+SUM(F5:F10) -> 259148.39 | G11: =+SUM(G5:G10) -> 1200 | H11: =+SUM(H5:H10) -> 0 | I11: =+SUM(I5:I10) -> 7200 | J11: =+SUM(J5:J10) -> 0 | K11: =+SUM(K5:K10) -> 8400 | L11: =+SUM(L5:L10) -> 250748
A14: Salary Statement of Contract Staff - Teaching for the month of August'26
A15: S.No. | B15: Name of the Employee | C15: Designation | D15: Monthly Salary | E15: Dean/Warden Allowance | F15: No.of Days Salary Payable | G15: Gross Salary | H15: PT | I15: TDS | J15: PF | K15: Other deductions | L15: Total Deductions | M15: Net Salary | N15: Contract Period
A16: 1 | B16: Dr.Narender Pendkar | C16: Visiting Research Professor | D16: 159100 | E16: 0 | F16: 31 | G16: =D16/31*F16 -> 159100 | H16: 200 | I16: 48000 | J16: 0 | K16: 650 | L16: =+SUM(H16:K16) -> 48850 | M16: =ROUND(G16-L16,0) -> 110250 | N16: 06.01.26 to 05.01.27
A17: 2 | B17: Dr.Atul K Varma | C17: Visiting Research Professor | D17: 108150 | E17: 5000 | F17: 31 | G17: =D17/31*F17+E17 -> 113150 | H17: 200 | I17: 1500 | J17: 0 | K17: 650 | L17: =+SUM(H17:K17) -> 2350 | M17: =ROUND(G17-L17,0) -> 110800
A18: 3 | B18: Dr.Rishabh Tripathi | C18: Visiting Assistant Professor(G-II) | D18: 90000 | E18: 0 | F18: 31 | G18: =D18/31*F18 -> 90000 | H18: 200 | I18: 0 | J18: 0 | K18: 650 | L18: =+SUM(H18:K18) -> 850 | M18: =ROUND(G18-L18,0) -> 89150 | N18: 31.10.25 to 30.10.26
A19: 4 | B19: Dr.Seekala Haritha | C19: Visiting Assistant Professor(G-II) | D19: 90000 | E19: 0 | F19: 31 | G19: =D19/31*F19 -> 90000 | H19: 200 | I19: 0 | J19: 0 | K19: 650 | L19: =+SUM(H19:K19) -> 850 | M19: =ROUND(G19-L19,0) -> 89150 | N19: 07.01.2026 to 06.01.2027
A20: 5 | B20: Dr.Ranju M.R | C20: Visiting Assistant Professor(G-II) | D20: 90000 | E20: 0 | F20: 31 | G20: =D20/31*F20 -> 90000 | H20: 200 | I20: 5000 | J20: 0 | K20: 650 | L20: =+SUM(H20:K20) -> 5850 | M20: =ROUND(G20-L20,0) -> 84150 | N20: 20.02.2026 to 19.02.2027
A21: 6 | B21: Dr.Sundaram Buchaiah | C21: Visiting Assistant Professor(G-II) | D21: 100000 | E21: 0 | F21: 31 | G21: =D21/31*F21 -> 100000 | H21: 200 | I21: 0 | J21: 0 | K21: 650 | L21: =+SUM(H21:K21) -> 850 | M21: =ROUND(G21-L21,0) -> 99150 | N21: 26.02.2026 to 25.02.2027
A22: 7 | B22: Dr.Shamiksha | C22: Visiting Assistant Professor(G-II) | D22: 90000 | E22: 0 | F22: 31 | G22: =D22/31*F22 -> 90000 | H22: 0 | I22: 0 | J22: 0 | K22: 0 | L22: =+SUM(H22:K22) -> 0 | M22: =ROUND(G22-L22,0) -> 90000 | N22: 27.07.2026 to 26.06.2027
A23: Total | D23: =+SUM(D16:D22) -> 727250 | G23: =+SUM(G16:G22) -> 732250 | H23: =+SUM(H16:H22) -> 1200 | I23: =+SUM(I16:I22) -> 54500 | J23: =+SUM(J16:J22) -> 0 | K23: =+SUM(K16:K22) -> 3900 | L23: =+SUM(L16:L22) -> 59600 | M23: =+SUM(M16:M22) -> 672650
A26: Medical Officer's Salary
A27: S.No. | B27: Name | C27: Month | D27: Monthly Honorarium | E27: Petrol/Mileage Allowance | F27: TDS@194J | G27: Total Deductions | H27: Net Amount | I27: Contract Period
A28: 1 | B28: Dr.Priyanka Sista | C28: August'26 | D28: =+ROUND(42000*0.903225806451613,0) -> 37935 | E28: 3000 | F28: =+D28*0.1 -> 3793.5 | G28: =+F28 -> 3793.5 | H28: =+D28+E28-G28 -> 37141.5 | I28: 29.08.25 to 28.08.26
A29: Grand Total | D29: =+SUM(D28:D28) -> 37935 | E29: =+SUM(E28:E28) -> 3000 | F29: =+SUM(F28:F28) -> 3793.5 | G29: =+SUM(G28:G28) -> 3793.5 | H29: =+SUM(H28:H28) -> 37141.5
M34: APPROVED /NOT APPROVED
B39: PREPARED BY | E39: VERIFIED BY | I39: VERIFIED BY
B40: (Y RAMA RAO) | E40: (Ch KALIKA DEVI) | I40: ( SATYANARAYAN MOHANTY)
B41: Jr SUPERINTENDENT | E41: ASSISTANT REGISTRAR (F&A) | I41: DEPUTY REGISTRAR | M41: (SHRI.RAM PHAL DWIVEDI)
M42: REGISTRAR

Sheet TDS
A1: S.No. | B1: Name of the Employee | C1: Basic | D1: DA 17 % | E1: TA | F1: HRA 16 % | G1: GTI | H1: Taxable Income | I1: Tax Regime | J1: TDS
A2: 1 | B2: Dr.V S R K Prasad | C2: 225000 | D2: 38250 | F2: 36000 | G2: 3591000 | H2: 3591000 | I2: Old | J2: 75000
A3: 2 | B3: Dr.B.Sridhar Reddy | C3: 144200 | D3: 24514 | F3: 23072 | G3: 2301432 | H3: 2301432 | I3: Old | J3: 31300
A4: 3 | B4: Dr. B Murali Krishna | C4: 78800 | D4: 13396 | E4: 4212 | F4: 12608 | G4: 1308192 | H4: 1308192 | I4: Old | J4: 11610
A5: 4 | B5: Dr. Rajat Jain | C5: 101500 | D5: 17255 | E5: 4212 | F5: 16240 | G5: 1670484 | H5: 1670484 | I5: New | J5: 20680
A6: 5 | B6: Dr. Deepak Amban Mishra | C6: 101500 | D6: 17255 | E6: 4212 | F6: 16240 | G6: 1670484 | H6: 1670484 | I6: New | J6: 20680
A7: 6 | B7: Dr. Ranjan Pramanik | C7: 101500 | D7: 17255 | E7: 4212 | F7: 16240 | G7: 1670484 | H7: 1670484 | I7: New | J7: 20680
A8: 7 | B8: Dr. Swambabu Varanasi | C8: 101500 | D8: 17255 | E8: 4212 | F8: 16240 | G8: 1670484 | H8: 1670484 | I8: Old | J8: 20040
A9: 8 | B9: Dr. Somnath Ghosh | C9: 101500 | D9: 17255 | E9: 4212 | F9: 16240 | G9: 1670484 | H9: 1670484 | I9: New | J9: 20680
A10: 9 | B10: Dr. Geddada Nagesh | C10: 101500 | D10: 17255 | E10: 4212 | F10: 16240 | G10: 1670484 | H10: 1670484 | I10: Old | J10: 20500
A11: 10 | B11: Dr. Randhi Ramunaidu | C11: 101500 | D11: 17255 | E11: 4212 | F11: 16240 | G11: 1670484 | H11: 1670484 | I11: New | J11: 20680
A12: 11 | B12: Dr. C.Veerabhadra Rao | C12: 101500 | D12: 17255 | E12: 4212 | F12: 16240 | G12: 1670484 | H12: 1670484 | I12: Old | J12: 20500
A13: 12 | B13: Dr. Kakati Himangshu | C13: 101500 | D13: 17255 | E13: 4212 | F13: 16240 | G13: 1670484 | H13: 1670484 | I13: New | J13: 20680
A14: 13 | B14: Dr. Arun Kumar Pujari | C14: 101500 | D14: 17255 | E14: 4212 | F14: 16240 | G14: 1670484 | H14: 1670484 | I14: Old | J14: 17570
A15: 14 | B15: Dr. T Hemanth Kumar | C15: 73200 | D15: 12444 | E15: 4212 | F15: 11712 | G15: 1218816 | H15: 1218816 | I15: Old | J15: 7980
... A30: 29 | B30: Mr.K Nagesh | C30: 35400 | D30: 6018 | E30: 2106 | F30: 5664 | G30: 590256 | H30: 590256 | I30: Old | J30: 0
B31: Total | C31: 2536000 | D31: 431120 | E31: 101088 | F31: 405760 | G31: 41687616 | H31: 41687616 | J31: 449750
C32: Consolidated Salary
A33: 1 | B33: ASV Ramanan | C33: 80000 | G33: 960000 | H33: 960000 | I33: Old | J33: 7890
A34: 2 | B34: Manasa | C34: 50000 | G34: 600000 | H34: 600000 | I34: Old | J34: 1660
C35: 130000 | G35: 1560000 | H35: 1560000 | I35: Old | J35: 9550
B36: Total | C36: =SUM(C33:C35) -> 260000 | J36: =SUM(J33:J35) -> 19100

Sheet Loan recovery 
A1: Loan Recovery statement
A2: Name of the Employee | B2: 43678 | C2: 43709 | D2: 43739 | E2: 43770 | F2: 43800 | G2: 43831 | H2: 43862 | I2: 43891 | J2: 43922 | K2: 43952 | L2: 43983 | M2: 44013 | N2: Amount recovered | O2: Amount to be recovered
A3: Somnath Ghosh | C3: 5000 | D3: 5000 | E3: 5000 | F3: 5000 | G3: 5000 | H3: 5000 | I3: 5000 | J3: 5000 | K3: 5000 | L3: 5000 | M3: 0 | N3: =SUM(C3:M3) -> 50000 | O3: =50000-N3 -> 0
A4: Randhi Ramunaidu | C4: 5000 | D4: 5000 | E4: 5000 | F4: 5000 | G4: 5000 | H4: 5000 | I4: 5000 | J4: 5000 | K4: 5000 | L4: 5000 | M4: 0 | N4: =SUM(C4:L4) -> 50000 | O4: =50000-N4 -> 0
A5: Chanchayya Gupta | B5: 5000 | C5: 5000 | D5: 5000 | E5: 5000 | F5: 5000 | G5: 5000 | H5: 5000 | I5: 5000 | J5: 5000 | K5: 5000 | L5: 0 | M5: 0 | N5: =SUM(B5:L5) -> 50000 | O5: =50000-N5 -> 0
A6: Samala Rathan | B6: 5000 | C6: 5000 | D6: 5000 | E6: 5000 | F6: 5000 | G6: 5000 | H6: 5000 | I6: 5000 | J6: 5000 | K6: 5000 | L6: 0 | M6: 0 | N6: =SUM(B6:L6) -> 50000 | O6: =50000-N6 -> 0
A7: Shailesh Kumar | B7: 5000 | C7: 5000 | D7: 5000 | E7: 5000 | F7: 5000 | G7: 5000 | H7: 5000 | I7: 5000 | J7: 5000 | K7: 5000 | L7: 0 | M7: 0 | N7: =SUM(B7:L7) -> 50000 | O7: =50000-N7 -> 0
A8: Venkata reddy | E8: 5000 | F8: 5000 | G8: 5000 | H8: 5000 | I8: 5000 | J8: 5000 | K8: 5000 | L8: 5000 | M8: 5000 | N8: =SUM(B8:M8) -> 45000 | O8: =50000-N8 -> 5000

Sheet Arrears on promotion 
A1: Arrears on account of promotion
A2: Name of the Faculty | B2: Date of promotion | C2: Basic Pay | D2: Upgraded Pay | E2: Difference in Pay | F2: No.of.Days | G2: Proportionate Basic | H2: DA | I2: HRA | J2: NPS Employer | K2: Gross Total | L2: TDS | M2: Less: NPS Employee share | N2: Less: NPS Employer share | O2: Net amount payable
A3: Dr.Geddada Nagesh | B3: 13th February 2025 | C3: 139400 | D3: 139600 | E3: =+D3-C3 -> 200 | F3: 16 | G3: =ROUND(E3*F3/28,0) -> 114 | H3: =ROUNDUP(G3*53/100,0) -> 61 | I3: =ROUND(G3*20/100,0) -> 23 | J3: =+ROUND(SUM(G3+H3)*14/100,0) -> 25 | K3: =ROUND(SUM(G3:J3,),0) -> 223 | L3: =ROUND(K3*10/100,0) -> 22 | M3: =+ROUNDUP(SUM(G3+H3)*10/100,0) -> 18 | N3: =+J3 -> 25 | O3: =ROUND(K3-L3-M3-N3,0) -> 158
B4: March'25 | C4: 139400 | D4: 139600 | E4: =+D4-C4 -> 200 | F4: 31 | G4: =ROUND(E4*F4/31,0) -> 200 | H4: =ROUNDUP(G4*53/100,0) -> 106 | I4: =ROUND(G4*20/100,0) -> 40 | J4: =+ROUND(SUM(G4+H4)*14/100,0) -> 43 | K4: =ROUND(SUM(G4:J4,),0) -> 389 | L4: =ROUND(K4*10/100,0) -> 39 | M4: =+ROUNDUP(SUM(G4+H4)*10/100,0) -> 31 | N4: =+J4 -> 43 | O4: =ROUND(K4-L4-M4-N4,0) -> 276
A6: Dr.Ch.Gupta Chanduluri | B6: 13th February 2025 | C6: 139400 | D6: 139600 | E6: =+D6-C6 -> 200 | F6: 16 | G6: =ROUND(E6*F6/28,0) -> 114 | H6: =ROUNDUP(G6*53/100,0) -> 61 | I6: =ROUND(G6*20/100,0) -> 23 | J6: =+ROUND(SUM(G6+H6)*14/100,0) -> 25 | K6: =ROUND(SUM(G6:J6,),0) -> 223 | L6: =ROUND(K6*10/100,0) -> 22 | M6: =+ROUNDUP(SUM(G6+H6)*10/100,0) -> 18 | N6: =+J6 -> 25 | O6: =ROUND(K6-L6-M6-N6,0) -> 158
B7: March'25 | C7: 139400 | D7: 139600 | E7: =+D7-C7 -> 200 | F7: 28 | G7: =ROUND(E7*F7/28,0) -> 200 | H7: =ROUNDUP(G7*53/100,0) -> 106 | I7: =ROUND(G7*20/100,0) -> 40 | J7: =+ROUND(SUM(G7+H7)*14/100,0) -> 43 | K7: =ROUND(SUM(G7:J7,),0) -> 389 | L7: =ROUND(K7*10/100,0) -> 39 | M7: =+ROUNDUP(SUM(G7+H7)*10/100,0) -> 31 | N7: =+J7 -> 43 | O7: =ROUND(K7-L7-M7-N7,0) -> 276
A9: Dr.Dipankar pal | B9: 13th February 2025 | C9: 135300 | D9: 139600 | E9: =+D9-C9 -> 4300 | F9: 16 | G9: =ROUND(E9*F9/28,0) -> 2457 | H9: =ROUNDUP(G9*53/100,0) -> 1303 | I9: =ROUND(G9*20/100,0) -> 491 | J9: =+ROUND(SUM(G9+H9)*14/100,0) -> 526 | K9: =ROUND(SUM(G9:J9,),0) -> 4777 | L9: =ROUND(K9*10/100,0) -> 478 | M9: =+ROUNDUP(SUM(G9+H9)*10/100,0) -> 376 | N9: =+J9 -> 526 | O9: =ROUND(K9-L9-M9-N9,0) -> 3397
B10: March'25 | C10: 135300 | D10: 139600 | E10: =+D10-C10 -> 4300 | F10: 31 | G10: =ROUND(E10*F10/31,0) -> 4300 | H10: =ROUNDUP(G10*53/100,0) -> 2279 | I10: =ROUND(G10*20/100,0) -> 860 | J10: =+ROUND(SUM(G10+H10)*14/100,0) -> 921 | K10: =ROUND(SUM(G10:J10,),0) -> 8360 | L10: =ROUND(K10*10/100,0) -> 836 | M10: =+ROUNDUP(SUM(G10+H10)*10/100,0) -> 658 | N10: =+J10 -> 921 | O10: =ROUND(K10-L10-M10-N10,0) -> 5945
A12: Dr.Siva sankar | B12: 13th February 2025 | C12: 131400 | D12: 139600 | E12: =+D12-C12 -> 8200 | F12: 16 | G12: =ROUND(E12*F12/28,0) -> 4686 | H12: =ROUNDUP(G12*53/100,0) -> 2484 | I12: =ROUND(G12*20/100,0) -> 937 | J12: =+ROUND(SUM(G12+H12)*14/100,0) -> 1004 | K12: =ROUND(SUM(G12:J12,),0) -> 9111 | L12: =ROUND(K12*10/100,0) -> 911 | M12: =+ROUNDUP(SUM(G12+H12)*10/100,0) -> 717 | N12: =+J12 -> 1004 | O12: =ROUND(K12-L12-M12-N12,0) -> 6479
B13: March'25 | C13: 131400 | D13: 139600 | E13: =+D13-C13 -> 8200 | F13: 31 | G13: =ROUND(E13*F13/31,0) -> 8200 | H13: =ROUNDUP(G13*53/100,0) -> 4346 | I13: =ROUND(G13*20/100,0) -> 1640 | J13: =+ROUND(SUM(G13+H13)*14/100,0) -> 1756 | K13: =ROUND(SUM(G13:J13,),0) -> 15942 | L13: =ROUND(K13*10/100,0) -> 1594 | M13: =+ROUNDUP(SUM(G13+H13)*10/100,0) -> 1255 | N13: =+J13 -> 1756 | O13: =ROUND(K13-L13-M13-N13,0) -> 11337
A15: Dr.Raka Monadal | B15: 13th February 2025 | C15: 131400 | D15: 139600 | E15: =+D15-C15 -> 8200 | F15: 16 | G15: =ROUND(E15*F15/28,0) -> 4686 | H15: =ROUNDUP(G15*53/100,0) -> 2484 | I15: =ROUND(G15*20/100,0) -> 937 | J15: =+ROUND(SUM(G15+H15)*14/100,0) -> 1004 | K15: =ROUND(SUM(G15:J15,),0) -> 9111 | L15: =ROUND(K15*10/100,0) -> 911 | M15: =+ROUNDUP(SUM(G15+H15)*10/100,0) -> 717 | N15: =+J15 -> 1004 | O15: =ROUND(K15-L15-M15-N15,0) -> 6479
B16: March'25 | C16: 131400 | D16: 139600 | E16: =+D16-C16 -> 8200 | F16: 31 | G16: =ROUND(E16*F16/31,0) -> 8200 | H16: =ROUNDUP(G16*53/100,0) -> 4346 | I16: =ROUND(G16*20/100,0) -> 1640 | J16: =+ROUND(SUM(G16+H16)*14/100,0) -> 1756 | K16: =ROUND(SUM(G16:J16,),0) -> 15942 | L16: =ROUND(K16*10/100,0) -> 1594 | M16: =+ROUNDUP(SUM(G16+H16)*10/100,0) -> 1255 | N16: =+J16 -> 1756 | O16: =ROUND(K16-L16-M16-N16,0) -> 11337
A17: Total | G17: =+SUM(G3:G16) -> 33157 | H17: =+SUM(H3:H16) -> 17576 | I17: =+SUM(I3:I16) -> 6631 | J17: =+SUM(J3:J16) -> 7103 | K17: =+SUM(K3:K16) -> 64467 | L17: =+SUM(L3:L16) -> 6446 | M17: =+SUM(M3:M16) -> 5076 | N17: =+SUM(N3:N16) -> 7103 | O17: =+SUM(O3:O16) -> 45842

Sheet Faculty 
J1: INDIAN INSTITUTE OF PETROLEUM AND ENERGY
A2: Salary Statement of Faculty for the month of August'26
A3: Sl.no | B3: Employee No | C3: Name of the Employee | D3: Designation | E3: Pay level | F3: Basic | G3: DA 60% | H3: TA( Rs.3600+ * DA@60%) | I3: HRA 20 % | J3: Dean / Warden Allowance | K3: NPS Employer share | L3: Gross Salary | M3: PT | N3: TDS | O3: NPS Employee share | P3: NPS Employer share | Q3: CGHS Contribution | R3: Other deductions | S3: Total Deductions | T3: Net Salary
A4: 1 | B4: TS1029 | C4: Dr.Vijaya Kumar Kopparapu | D4: Professor | E4: APL 14A | F4: 213800 | G4: =ROUND(F4*60%,0) -> 128280 | H4: =3600*160% -> 5760 | I4: =ROUND(F4*20/100,0) -> 42760 | J4: 3000 | K4: =+ROUND(SUM(F4+G4)*14/100,0) -> 47891 | L4: =+SUM(F4:K4) -> 441491 | M4: 200 | N4: 90000 | O4: =+ROUND(SUM(F4+G4)*0.1,0) -> 34208 | P4: =+K4 -> 47891 | Q4: 1000 | R4: 482 | S4: =SUM(M4:R4) -> 173781 | T4: =+L4-S4 -> 267710
A5: 2 | B5: TS1027 | C5: Dr.Ambati Seshagiri Rao | D5: Professor | E5: APL 14A | F5: 184500 | G5: =ROUND(F5*60%,0) -> 110700 | H5: =3600*160% -> 5760 | I5: =ROUND(F5*20/100,0) -> 36900 | J5: 3000 | K5: =+ROUND(SUM(F5+G5)*14/100,0) -> 41328 | L5: =+SUM(F5:K5) -> 382188 | M5: 200 | N5: 70000 | O5: =+ROUND(SUM(F5+G5)*0.1,0) -> 29520 | P5: =+K5 -> 41328 | Q5: 1000 | R5: 0 | S5: =SUM(M5:R5) -> 142048 | T5: =+L5-S5 -> 240140
A6: 3 | B6: TS1002 | C6: Dr. Somnath Ghosh | D6: Associate Professor | E6: APL 13A2 | F6: 152500 | G6: =ROUND(F6*60%,0) -> 91500 | H6: =3600*160% -> 5760 | I6: =ROUND(F6*20/100,0) -> 30500 | J6: 0 | K6: =+ROUND(SUM(F6+G6)*14/100,0) -> 34160 | L6: =+SUM(F6:K6) -> 314420 | M6: 200 | N6: 50000 | O6: =+ROUND(SUM(F6+G6)*0.1,0) -> 24400 | P6: =+K6 -> 34160 | Q6: 1000 | R6: 0 | S6: =SUM(M6:R6) -> 109760 | T6: =+L6-S6 -> 204660
A7: 4 | B7: TS1003 | C7: Dr. Deepak Amban Mishra | D7: Associate Professor | E7: APL 13A2 | F7: 152500 | G7: =ROUND(F7*60%,0) -> 91500 | H7: =3600*160% -> 5760 | I7: =ROUND(F7*20/100,0) -> 30500 | J7: 0 | K7: =+ROUND(SUM(F7+G7)*14/100,0) -> 34160 | L7: =+SUM(F7:K7) -> 314420 | M7: 200 | N7: 50000 | O7: =+ROUND(SUM(F7+G7)*0.1,0) -> 24400 | P7: =+K7 -> 34160 | Q7: 1000 | R7: 0 | S7: =SUM(M7:R7) -> 109760 | T7: =+L7-S7 -> 204660
A8: 5 | B8: TS1004 | C8: Dr. Randhi Ramunaidu | D8: Associate Professor | E8: APL 13A2 | F8: 152500 | G8: =ROUND(F8*60%,0) -> 91500 | H8: =3600*160% -> 5760 | I8: =ROUND(F8*20/100,0) -> 30500 | J8: 0 | K8: =+ROUND(SUM(F8+G8)*14/100,0) -> 34160 | L8: =+SUM(F8:K8) -> 314420 | M8: 200 | N8: 60000 | O8: =+ROUND(SUM(F8+G8)*0.1,0) -> 24400 | P8: =+K8 -> 34160 | Q8: 1000 | R8: 0 | S8: =SUM(M8:R8) -> 119760 | T8: =+L8-S8 -> 194660
A9: 6 | B9: TS1005 | C9: Dr. Arun Kumar Pujari | D9: Associate Professor | E9: APL 13A2 | F9: 152500 | G9: =ROUND(F9*60%,0) -> 91500 | H9: =3600*160% -> 5760 | I9: =ROUND(F9*20/100,0) -> 30500 | J9: 0 | K9: =+ROUND(SUM(F9+G9)*14/100,0) -> 34160 | L9: =+SUM(F9:K9) -> 314420 | M9: 200 | N9: 30000 | O9: =+ROUND(SUM(F9+G9)*0.1,0) -> 24400 | P9: =+K9 -> 34160 | Q9: 1000 | R9: 0 | S9: =SUM(M9:R9) -> 89760 | T9: =+L9-S9 -> 224660
A10: 7 | B10: TS1006 | C10: Dr. T Hemanth Kumar | D10: Associate Professor | E10: APL 13A2 | F10: 148100 | G10: =ROUND(F10*60%,0) -> 88860 | H10: =3600*160% -> 5760 | I10: =ROUND(F10*20/100,0) -> 29620 | J10: 0 | K10: =+ROUND(SUM(F10+G10)*14/100,0) -> 33174 | L10: =+SUM(F10:K10) -> 305514 | M10: 200 | N10: 60000 | O10: =+ROUND(SUM(F10+G10)*0.1,0) -> 23696 | P10: =+K10 -> 33174 | Q10: 1000 | R10: 0 | S10: =SUM(M10:R10) -> 118070 | T10: =+L10-S10 -> 187444
A11: 8 | B11: TS1007 | C11: Dr. C.Veerabhadra Rao | D11: Associate Professor | E11: APL 13A2 | F11: 152500 | G11: =ROUND(F11*60%,0) -> 91500 | H11: =3600*160% -> 5760 | I11: =ROUND(F11*20/100,0) -> 30500 | J11: 3000 | K11: =+ROUND(SUM(F11+G11)*14/100,0) -> 34160 | L11: =+SUM(F11:K11) -> 317420 | M11: 200 | N11: 60000 | O11: =+ROUND(SUM(F11+G11)*0.1,0) -> 24400 | P11: =+K11 -> 34160 | Q11: 1000 | R11: 0 | S11: =SUM(M11:R11) -> 119760 | T11: =+L11-S11 -> 197660
A12: 9 | B12: TS1008 | C12: Dr. Chanchayya Gupta Ch | D12: Associate Professor | E12: APL 13A2 | F12: 152500 | G12: =ROUND(F12*60%,0) -> 91500 | H12: =3600*160% -> 5760 | I12: =ROUND(F12*20/100,0) -> 30500 | J12: 0 | K12: =+ROUND(SUM(F12+G12)*14/100,0) -> 34160 | L12: =+SUM(F12:K12) -> 314420 | M12: 200 | N12: 80000 | O12: =+ROUND(SUM(F12+G12)*0.1,0) -> 24400 | P12: =+K12 -> 34160 | Q12: 1000 | R12: 0 | S12: =SUM(M12:R12) -> 139760 | T12: =+L12-S12 -> 174660
A13: 10 | B13: TS1009 | C13: Dr. Geddada Nagesh | D13: Associate Professor | E13: APL 13A2 | F13: 152500 | G13: =ROUND(F13*60%,0) -> 91500 | H13: =3600*160% -> 5760 | I13: =ROUND(F13*20/100,0) -> 30500 | J13: 0 | K13: =+ROUND(SUM(F13+G13)*14/100,0) -> 34160 | L13: =+SUM(F13:K13) -> 314420 | M13: 200 | N13: 60000 | O13: =+ROUND(SUM(F13+G13)*0.1,0) -> 24400 | P13: =+K13 -> 34160 | Q13: 1000 | R13: 0 | S13: =SUM(M13:R13) -> 119760 | T13: =+L13-S13 -> 194660
A14: 11 | B14: TS1011 | C14: Dr. P Aparoy | D14: Associate Professor | E14: APL 13A2 | F14: 152500 | G14: =ROUND(F14*60%,0) -> 91500 | H14: =3600*160% -> 5760 | I14: =ROUND(F14*20/100,0) -> 30500 | J14: 3000 | K14: =+ROUND(SUM(F14+G14)*14/100,0) -> 34160 | L14: =+SUM(F14:K14) -> 317420 | M14: 200 | N14: 65000 | O14: =+ROUND(SUM(F14+G14)*0.1,0) -> 24400 | P14: =+K14 -> 34160 | Q14: 1000 | R14: 0 | S14: =SUM(M14:R14) -> 124760 | T14: =+L14-S14 -> 192660
A15: 12 | B15: TS1012 | C15: Dr. Rajat Jain | D15: Associate Professor | E15: APL 13A2 | F15: 152500 | G15: =ROUND(F15*60%,0) -> 91500 | H15: =3600*160% -> 5760 | I15: =ROUND(F15*20/100,0) -> 30500 | J15: 3000 | K15: =+ROUND(SUM(F15+G15)*14/100,0) -> 34160 | L15: =+SUM(F15:K15) -> 317420 | M15: 200 | N15: 50000 | O15: =+ROUND(SUM(F15+G15)*0.1,0) -> 24400 | P15: =+K15 -> 34160 | Q15: 1000 | R15: 0 | S15: =SUM(M15:R15) -> 109760 | T15: =+L15-S15 -> 207660
... A31: 28 | B31: TS1030 | C31: Dr.Sharon H | D31: Asst.Professor | E31: APL 12 | F31: 107600 | G31: =ROUND(F31*60%,0) -> 64560 | H31: =3600*160% -> 5760 | I31: =ROUND(F31*20/100,0) -> 21520 | J31: 0 | K31: =+ROUND(SUM(F31+G31)*14/100,0) -> 24102 | L31: =+SUM(F31:K31) -> 223542 | M31: 200 | N31: 25000 | O31: =+ROUND(SUM(F31+G31)*0.1,0) -> 17216 | P31: =+K31 -> 24102 | Q31: 1000 | R31: 0 | S31: =SUM(M31:R31) -> 67518 | T31: =+L31-S31 -> 156024
A32: 29 | B32: TS1032 | C32: Dr.Roshan Kumar Singh | D32: Asst.Professor | E32: APL 12 | F32: 107600 | G32: =ROUND(F32*60%,0) -> 64560 | H32: 5760 | I32: =ROUND(F32*20/100,0) -> 21520 | J32: 0 | K32: =+ROUND(SUM(F32+G32)*14/100,0) -> 24102 | L32: =+SUM(F32:K32) -> 223542 | M32: 200 | N32: 28000 | O32: =+ROUND(SUM(F32+G32)*0.1,0) -> 17216 | P32: =+K32 -> 24102 | Q32: 1000 | R32: 0 | S32: =SUM(M32:R32) -> 70518 | T32: =+L32-S32 -> 153024
A33: 30 | B33: TS1036 | C33: Dr.Subham Bose | D33: Asst.Professor | E33: APL 12 | F33: 104500 | G33: =ROUND(F33*60%,0) -> 62700 | H33: =3600*160% -> 5760 | I33: =ROUND(F33*20/100,0) -> 20900 | J33: 0 | K33: =+ROUND(SUM(F33+G33)*14/100,0) -> 23408 | L33: =+SUM(F33:K33) -> 217268 | M33: 200 | N33: 30000 | O33: =+ROUND(SUM(F33+G33)*0.1,0) -> 16720 | P33: =+K33 -> 23408 | Q33: 1000 | R33: 0 | S33: =SUM(M33:R33) -> 71328 | T33: =+L33-S33 -> 145940
A34: 31 | B34: TS1033 | C34: Dr.Santosh Kumar Senapathi | D34: Asst.Professor | E34: APL12 | F34: 104500 | G34: =ROUND(F34*60%,0) -> 62700 | H34: =3600*160% -> 5760 | I34: =ROUND(F34*20/100,0) -> 20900 | J34: 5000 | K34: =+ROUND(SUM(F34+G34)*14/100,0) -> 23408 | L34: =+SUM(F34:K34) -> 222268 | M34: 200 | N34: 20000 | O34: =+ROUND(SUM(F34+G34)*0.1,0) -> 16720 | P34: =+K34 -> 23408 | Q34: 1000 | R34: 0 | S34: =SUM(M34:R34) -> 61328 | T34: =+L34-S34 -> 160940 | V34: 159121
A35: 32 | B35: TS1034 | C35: Dr.Elizabeth Eldo | D35: Asst.Professor | E35: APL 11 | F35: =89900 -> 89900 | G35: =ROUND(F35*60%,0) -> 53940 | H35: =3600*160% -> 5760 | I35: =ROUND(F35*20/100,0) -> 17980 | J35: 0 | K35: =+ROUND(SUM(F35+G35)*14/100,0) -> 20138 | L35: =+SUM(F35:K35) -> 187718 | M35: 200 | N35: 15000 | O35: =+ROUND(SUM(F35+G35)*0.1,0) -> 14384 | P35: =+K35 -> 20138 | Q35: 650 | R35: 0 | S35: =SUM(M35:R35) -> 50372 | T35: =+L35-S35 -> 137346 | V35: =+V34-T34 -> -1819
A36: 33 | B36: TS1037 | C36: Dr.Juhi Chaudhary | D36: Asst.Professor | E36: APL 12 | F36: 104500 | G36: =ROUND(F36*60%,0) -> 62700 | H36: =3600*160% -> 5760 | I36: =ROUND(F36*20/100,0) -> 20900 | J36: 0 | K36: =+ROUND(SUM(F36+G36)*14/100,0) -> 23408 | L36: =+SUM(F36:K36) -> 217268 | M36: 200 | N36: 30000 | O36: =+ROUND(SUM(F36+G36)*0.1,0) -> 16720 | P36: =+K36 -> 23408 | Q36: 1000 | R36: 0 | S36: =SUM(M36:R36) -> 71328 | T36: =+L36-S36 -> 145940
A37: 34 | B37: TS1038 | C37: Dr.Ganesh Kumar | D37: Asst.Professor | E37: APL 11 | F37: =89900 -> 89900 | G37: =ROUND(F37*60%,0) -> 53940 | H37: =3600*160% -> 5760 | I37: =ROUND(F37*20/100,0) -> 17980 | J37: 0 | K37: =+ROUND(SUM(F37+G37)*14/100,0) -> 20138 | L37: =+SUM(F37:K37) -> 187718 | M37: 200 | N37: 20000 | O37: =+ROUND(SUM(F37+G37)*0.1,0) -> 14384 | P37: =+K37 -> 20138 | Q37: 650 | R37: 0 | S37: =SUM(M37:R37) -> 55372 | T37: =+L37-S37 -> 132346
A38: Total | F38: =+SUM(F4:F37) -> 4597200 | G38: =+SUM(G4:G37) -> 2758320 | H38: =+SUM(H4:H37) -> 195840 | I38: =+SUM(I4:I37) -> 919440 | J38: =+SUM(J4:J37) -> 29000 | K38: =+SUM(K4:K37) -> 1029771 | L38: =+SUM(L4:L37) -> 9529571 | M38: =+SUM(M4:M37) -> 6800 | ... T38: =+SUM(T4:T37) -> 6238126
A39: * Rs.5760/- is deducted towards the Transport allowance for the month of June'26
R43: APPROVED /NOT APPROVED
B48: PREPARED BY | G48: VERIFIED BY | L48: VERIFIED BY
B49: (Y RAMA RAO) | G49: (Ch KALIKA DEVI) | L49: ( SATYANARAYAN MOHANTY)
B50: Jr SUPERINTENDENT | G50: =+Contract!E41 -> ASSISTANT REGISTRAR (F&A) | L50: DEPUTY REGISTRAR | R50: (SHRI.RAM PHAL DWIVEDI)
R51: REGISTRAR

Sheet Arrears 
A1: Arrears on account of promotion
A2: Name of the Faculty | B2: Basic Pay | C2: Upgraded Pay | D2: Difference in Pay | E2: No.of.Days | F2: Proportionate Basic | G2: DA | H2: HRA | I2: NPS Employer | J2: Gross Total | K2: Less: NPS Employee share | L2: Less: NPS Employer share | M2: Net amount payable
A3: Dr.Geddada Nagesh | B3: 139400 | C3: 139600 | D3: =+C3-B3 -> 200 | E3: 30 | F3: =ROUND(D3*E3/30,0) -> 200 | G3: =ROUNDUP(F3*55/100,0) -> 110 | H3: =ROUND(F3*20/100,0) -> 40 | I3: =+ROUND(SUM(F3+G3)*14/100,0) -> 43 | J3: =ROUND(SUM(F3:I3,),0) -> 393 | K3: =+ROUNDUP(SUM(F3+G3)*10/100,0) -> 31 | L3: =+I3 -> 43 | M3: =+J3-K3-L3 -> 319
A4: Dr.Ch.Gupta Chanduluri | B4: 139400 | C4: 139600 | D4: =+C4-B4 -> 200 | E4: 30 | F4: =ROUND(D4*E4/30,0) -> 200 | G4: =ROUNDUP(F4*55/100,0) -> 110 | H4: =ROUND(F4*20/100,0) -> 40 | I4: =+ROUND(SUM(F4+G4)*14/100,0) -> 43 | J4: =ROUND(SUM(F4:I4,),0) -> 393 | K4: =+ROUNDUP(SUM(F4+G4)*10/100,0) -> 31 | L4: =+I4 -> 43 | M4: =+J4-K4-L4 -> 319
A5: Dr.Dipankar pal | B5: 135300 | C5: 139600 | D5: =+C5-B5 -> 4300 | E5: 30 | F5: =ROUND(D5*E5/30,0) -> 4300 | G5: =ROUNDUP(F5*55/100,0) -> 2365 | H5: =ROUND(F5*20/100,0) -> 860 | I5: =+ROUND(SUM(F5+G5)*14/100,0) -> 933 | J5: =ROUND(SUM(F5:I5,),0) -> 8458 | K5: =+ROUNDUP(SUM(F5+G5)*10/100,0) -> 667 | L5: =+I5 -> 933 | M5: =+J5-K5-L5 -> 6858
A6: Dr.Siva sankar | B6: 131400 | C6: 139600 | D6: =+C6-B6 -> 8200 | E6: 30 | F6: =ROUND(D6*E6/30,0) -> 8200 | G6: =ROUNDUP(F6*55/100,0) -> 4510 | H6: =ROUND(F6*20/100,0) -> 1640 | I6: =+ROUND(SUM(F6+G6)*14/100,0) -> 1779 | J6: =ROUND(SUM(F6:I6,),0) -> 16129 | K6: =+ROUNDUP(SUM(F6+G6)*10/100,0) -> 1271 | L6: =+I6 -> 1779 | M6: =+J6-K6-L6 -> 13079
A7: Dr.Raka Monadal | B7: 131400 | C7: 139600 | D7: =+C7-B7 -> 8200 | E7: 30 | F7: =ROUND(D7*E7/30,0) -> 8200 | G7: =ROUNDUP(F7*55/100,0) -> 4510 | H7: =ROUND(F7*20/100,0) -> 1640 | I7: =+ROUND(SUM(F7+G7)*14/100,0) -> 1779 | J7: =ROUND(SUM(F7:I7,),0) -> 16129 | K7: =+ROUNDUP(SUM(F7+G7)*10/100,0) -> 1271 | L7: =+I7 -> 1779 | M7: =+J7-K7-L7 -> 13079
A8: Total | F8: =+SUM(F3:F7) -> 21100 | G8: =+SUM(G3:G7) -> 11605 | H8: =+SUM(H3:H7) -> 4220 | I8: =+SUM(I3:I7) -> 4577 | J8: =+SUM(J3:J7) -> 41502 | K8: =+SUM(K3:K7) -> 3271 | L8: =+SUM(L3:L7) -> 4577 | M8: =+SUM(M3:M7) -> 33654

Sheet Staff
E1: INDIAN INSTITUTE OF PETROLEUM AND ENERGY
A3: Salary Statement of Non Teaching Staff for the month of August 26
A4: Sl.No | B4: Employee No | C4: Name of the Employee | D4: Designation | E4: Pay Scale | F4: Basic | G4: DA 60% | H4: TA | I4: HRA 20 % | J4: NPS Employer Share | K4: Gross salary | L4: PT | M4: TDS | N4: NPS Employee share | O4: NPS Employer share | P4: CGHS Contribution | Q4: Other Recovery | R4: Total Deductions | S4: Net Salary
A5: 1 | B5: NT1022 | C5: Shri. Ramphal Dwivedi | D5: Registrar | E5: Level-14 | F5: 182700 | G5: =ROUND(F5*60%,0) -> 109620 | H5: 0 | I5: 0 | J5: =ROUND(SUM(F5+G5)*0.14,0) -> 40925 | K5: =SUM(F5:J5) -> 333245 | L5: 200 | M5: 60000 | N5: =ROUND(SUM(F5+G5)*0.1,0) -> 29232 | O5: =+J5 -> 40925 | P5: 1000 | Q5: 0 | R5: =SUM(L5:Q5) -> 131357 | S5: =+K5-R5 -> 201888
A6: 2 | B6: NT1001 | C6: Dr. B Murali Krishna | D6: Joint Registrar | E6: Level-13 | F6: 130600 | G6: =ROUND(F6*60%,0) -> 78360 | H6: =3600*160% -> 5760 | I6: =ROUND(F6*20/100,0) -> 26120 | J6: =ROUND(SUM(F6+G6)*0.14,0) -> 29254 | K6: =SUM(F6:J6) -> 270094 | L6: 200 | M6: 35000 | N6: =ROUND(SUM(F6+G6)*0.1,0) -> 20896 | O6: =+J6 -> 29254 | P6: 1000 | Q6: 0 | R6: =SUM(L6:Q6) -> 86350 | S6: =+K6-R6 -> 183744
A7: 3 | B7: NT1024 | C7: Shri P V Narayana Rao | D7: Superintendent Engineer | E7: Level-13 | F7: 119500 | G7: =+ROUND(155900*0.6,0) -> 93540 | H7: =3600*160% -> 5760 | I7: =+ROUND(155900*0.2,0) -> 31180 | J7: =+ROUND(SUM(F7+G7)*0.14,0) -> 29826 | K7: =SUM(F7:J7) -> 279806 | L7: 200 | M7: 50000 | N7: =+ROUND(SUM(F7+G7)*0.1,0) -> 21304 | O7: =+J7 -> 29826 | P7: 1000 | Q7: 0 | R7: =SUM(L7:Q7) -> 102330 | S7: =+K7-R7 -> 177476
A8: 4 | B8: NTS1027 | C8: Shri.Satya Narayan Mohanty | D8: Deputy Registrar (F&A) | E8: Level-12 | F8: 83600 | G8: =ROUND(F8*60%,0) -> 50160 | H8: =3600*160% -> 5760 | I8: =ROUND(F8*20/100,0) -> 16720 | J8: =ROUND(SUM(F8+G8)*0.14,0) -> 18726 | K8: =SUM(F8:J8) -> 174966 | L8: 200 | M8: 10000 | N8: =ROUND(SUM(F8+G8)*0.1,0) -> 13376 | O8: =+J8 -> 18726 | P8: 1000 | Q8: 0 | R8: =SUM(L8:Q8) -> 43302 | S8: =+K8-R8 -> 131664
A9: 5 | B9: NT1023 | C9: Mr. Sanyasi Naidu Paila | D9: Junior Technical Officer | E9: Level-10 | F9: 61300 | G9: =ROUND(F9*60%,0) -> 36780 | H9: =3600*160% -> 5760 | I9: =ROUND(F9*20/100,0) -> 12260 | J9: =ROUND(SUM(F9+G9)*0.14,0) -> 13731 | K9: =SUM(F9:J9) -> 129831 | L9: 200 | M9: 0 | N9: =ROUND(SUM(F9+G9)*0.1,0) -> 9808 | O9: =+J9 -> 13731 | P9: 650 | Q9: 0 | R9: =SUM(L9:Q9) -> 24389 | S9: =+K9-R9 -> 105442
A10: 6 | B10: NT1002 | C10: Mr. K Rama Krishna | D10: Assistant Registrar | E10: Level-10 | F10: 59500 | G10: =ROUND(F10*60%,0) -> 35700 | H10: =3600*160% -> 5760 | I10: =ROUND(F10*20/100,0) -> 11900 | J10: =ROUND(SUM(F10+G10)*0.14,0) -> 13328 | K10: =SUM(F10:J10) -> 126188 | L10: 200 | M10: 5000 | N10: =ROUND(SUM(F10+G10)*0.1,0) -> 9520 | O10: =+J10 -> 13328 | P10: 650 | Q10: 0 | R10: =SUM(L10:Q10) -> 28698 | S10: =+K10-R10 -> 97490
A11: 7 | B11: NT1004 | C11: Mrs. Ch Kalika Devi | D11: Assistant Registrar | E11: Level-10 | F11: 59500 | G11: =ROUND(F11*60%,0) -> 35700 | H11: =3600*160% -> 5760 | I11: =ROUND(F11*20/100,0) -> 11900 | J11: =ROUND(SUM(F11+G11)*0.14,0) -> 13328 | K11: =SUM(F11:J11) -> 126188 | L11: 200 | M11: 0 | N11: =ROUND(SUM(F11+G11)*0.1,0) -> 9520 | O11: =+J11 -> 13328 | P11: 650 | Q11: 0 | R11: =SUM(L11:Q11) -> 23698 | S11: =+K11-R11 -> 102490
A12: 8 | B12: NT1025 | C12: Dr.Aditya Kumar Singh | D12: Assistant Registrar | E12: Level-10 | F12: 56100 | G12: =ROUND(F12*60%,0) -> 33660 | H12: =3600*160% -> 5760 | I12: =ROUND(F12*20/100,0) -> 11220 | J12: =ROUND(SUM(F12+G12)*0.14,0) -> 12566 | K12: =SUM(F12:J12) -> 119306 | L12: 200 | M12: 0 | N12: =ROUND(SUM(F12+G12)*0.1,0) -> 8976 | O12: =+J12 -> 12566 | P12: 650 | Q12: 0 | R12: =SUM(L12:Q12) -> 22392 | S12: =+K12-R12 -> 96914
A13: 9 | B13: NT1026 | C13: Mr.Sachidananda Rath | D13: Assistant Registrar | E13: Level-10 | F13: 65000 | G13: =ROUND(F13*60%,0) -> 39000 | H13: =3600*160% -> 5760 | I13: =ROUND(F13*20/100,0) -> 13000 | J13: =ROUND(SUM(F13+G13)*0.14,0) -> 14560 | K13: =SUM(F13:J13) -> 137320 | L13: 200 | M13: 0 | N13: =ROUND(SUM(F13+G13)*0.1,0) -> 10400 | O13: =+J13 -> 14560 | P13: 650 | Q13: 0 | R13: =SUM(L13:Q13) -> 25810 | S13: =+K13-R13 -> 111510
A14: 10 | B14: NT1006 | C14: Mr. G. Shiva Kumar | D14: Assistant Engineer | E14: Level-7 | F14: 49000 | G14: =ROUND(F14*60%,0) -> 29400 | H14: =1800*160% -> 2880 | I14: =ROUND(F14*20/100,0) -> 9800 | J14: =ROUND(SUM(F14+G14)*0.14,0) -> 10976 | K14: =SUM(F14:J14) -> 102056 | L14: 200 | M14: 0 | N14: =ROUND(SUM(F14+G14)*0.1,0) -> 7840 | O14: =+J14 -> 10976 | P14: 650 | Q14: 0 | R14: =SUM(L14:Q14) -> 19666 | S14: =+K14-R14 -> 82390
A15: 11 | B15: NT1007 | C15: Mr. K Nagesh | D15: Assistant Engineer | E15: Level-7 | F15: 49000 | G15: =ROUND(F15*60%,0) -> 29400 | H15: =1800*160% -> 2880 | I15: =ROUND(F15*20/100,0) -> 9800 | J15: =ROUND(SUM(F15+G15)*0.14,0) -> 10976 | K15: =SUM(F15:J15) -> 102056 | L15: 200 | M15: 0 | N15: =ROUND(SUM(F15+G15)*0.1,0) -> 7840 | O15: =+J15 -> 10976 | P15: 650 | Q15: 0 | R15: =SUM(L15:Q15) -> 19666 | S15: =+K15-R15 -> 82390
A16: 12 | B16: NT1005 | C16: Mr. Y Rama Rao | D16: Junior Superintendent | E16: Level-6 | F16: 37600 | G16: =ROUND(F16*60%,0) -> 22560 | H16: =1800*160% -> 2880 | I16: =ROUND(F16*20/100,0) -> 7520 | J16: =ROUND(SUM(F16+G16)*0.14,0) -> 8422 | K16: =SUM(F16:J16) -> 78982 | L16: 200 | M16: 0 | N16: =ROUND(SUM(F16+G16)*0.1,0) -> 6016 | O16: =+J16 -> 8422 | P16: 450 | Q16: 0 | R16: =SUM(L16:Q16) -> 15088 | S16: =+K16-R16 -> 63894
A17: 13 | B17: NT1013 | C17: Mr. Somesh Katta | D17: Senior Lab.Asst | E17: Level-5 | F17: 30100 | G17: =ROUND(F17*60%,0) -> 18060 | H17: =1800*160% -> 2880 | I17: =ROUND(F17*20/100,0) -> 6020 | J17: =ROUND(SUM(F17+G17)*0.14,0) -> 6742 | K17: =SUM(F17:J17) -> 63802 | L17: 200 | M17: 0 | N17: =ROUND(SUM(F17+G17)*0.1,0) -> 4816 | O17: =+J17 -> 6742 | P17: 250 | Q17: 0 | R17: =SUM(L17:Q17) -> 12008 | S17: =+K17-R17 -> 51794
A18: 14 | B18: NT1014 | C18: Mr. Surendra Ratnala | D18: Senior Assistant | E18: Level-5 | F18: 30100 | G18: =ROUND(F18*60%,0) -> 18060 | H18: =1800*160% -> 2880 | I18: =ROUND(F18*20/100,0) -> 6020 | J18: =ROUND(SUM(F18+G18)*0.14,0) -> 6742 | K18: =SUM(F18:J18) -> 63802 | L18: 200 | M18: 0 | N18: =ROUND(SUM(F18+G18)*0.1,0) -> 4816 | O18: =+J18 -> 6742 | P18: 250 | Q18: 0 | R18: =SUM(L18:Q18) -> 12008 | S18: =+K18-R18 -> 51794
A19: 15 | B19: NT1015 | C19: Dr. Satyaprasad Yerra | D19: Senior Lab.Asst | E19: Level-5 | F19: 30100 | G19: =ROUND(F19*60%,0) -> 18060 | H19: =1800*160% -> 2880 | I19: =ROUND(F19*20/100,0) -> 6020 | J19: =ROUND(SUM(F19+G19)*0.14,0) -> 6742 | K19: =SUM(F19:J19) -> 63802 | L19: 200 | M19: 0 | N19: =ROUND(SUM(F19+G19)*0.1,0) -> 4816 | O19: =+J19 -> 6742 | P19: 250 | Q19: 0 | R19: =SUM(L19:Q19) -> 12008 | S19: =+K19-R19 -> 51794
A20: 16 | B20: NT1016 | C20: Mr. Nulu Praveen Kumar | D20: Senior Lab.Asst | E20: Level-5 | F20: 30100 | G20: =ROUND(F20*60%,0) -> 18060 | H20: =1800*160% -> 2880 | I20: =ROUND(F20*20/100,0) -> 6020 | J20: =ROUND(SUM(F20+G20)*0.14,0) -> 6742 | K20: =SUM(F20:J20) -> 63802 | L20: 200 | M20: 0 | N20: =ROUND(SUM(F20+G20)*0.1,0) -> 4816 | O20: =+J20 -> 6742 | P20: 250 | Q20: 40 | R20: =SUM(L20:Q20) -> 12048 | S20: =+K20-R20 -> 51754
A21: 17 | B21: NT1018 | C21: Mr.Goru Lakshmi Papa Rao | D21: Senior Lab.Asst | E21: Level-5 | F21: 30100 | G21: =ROUND(F21*60%,0) -> 18060 | H21: =1800*160% -> 2880 | I21: =ROUND(F21*20/100,0) -> 6020 | J21: =ROUND(SUM(F21+G21)*0.14,0) -> 6742 | K21: =SUM(F21:J21) -> 63802 | L21: 200 | M21: 0 | N21: =ROUND(SUM(F21+G21)*0.1,0) -> 4816 | O21: =+J21 -> 6742 | P21: 250 | Q21: 94 | R21: =SUM(L21:Q21) -> 12102 | S21: =+K21-R21 -> 51700
A22: 18 | B22: NT1019 | C22: Mr. Bidyadhoro Majhi | D22: Senior Assistant | E22: Level-5 | F22: 30100 | G22: =ROUND(F22*60%,0) -> 18060 | H22: =1800*160% -> 2880 | I22: =ROUND(F22*20/100,0) -> 6020 | J22: =ROUND(SUM(F22+G22)*0.14,0) -> 6742 | K22: =SUM(F22:J22) -> 63802 | L22: 200 | M22: 0 | N22: =ROUND(SUM(F22+G22)*0.1,0) -> 4816 | O22: =+J22 -> 6742 | P22: 250 | Q22: 0 | R22: =SUM(L22:Q22) -> 12008 | S22: =+K22-R22 -> 51794
A23: 19 | B23: NT1011 | C23: Mr. Appala Murthy N | D23: Junior Assistant | E23: Level-3 | F23: 24500 | G23: =ROUND(F23*60%,0) -> 14700 | H23: =1800*160% -> 2880 | I23: =ROUND(F23*20/100,0) -> 4900 | J23: =ROUND(SUM(F23+G23)*0.14,0) -> 5488 | K23: =SUM(F23:J23) -> 52468 | L23: 200 | M23: 0 | N23: =ROUND(SUM(F23+G23)*0.1,0) -> 3920 | O23: =+J23 -> 5488 | P23: 250 | Q23: 0 | R23: =SUM(L23:Q23) -> 9858 | S23: =+K23-R23 -> 42610
A24: 20 | B24: NT1012 | C24: Mr. U. Rambabu | D24: Junior Assistant | E24: Level-3 | F24: 24500 | G24: =ROUND(F24*60%,0) -> 14700 | H24: =1800*160% -> 2880 | I24: =ROUND(F24*20/100,0) -> 4900 | J24: =ROUND(SUM(F24+G24)*0.14,0) -> 5488 | K24: =SUM(F24:J24) -> 52468 | L24: 200 | M24: 0 | N24: =ROUND(SUM(F24+G24)*0.1,0) -> 3920 | O24: =+J24 -> 5488 | P24: 250 | Q24: 80 | R24: =SUM(L24:Q24) -> 9938 | S24: =+K24-R24 -> 42530
A25: Total | F25: =+SUM(F5:F24) -> 1183000 | G25: =+SUM(G5:G24) -> 731640 | H25: =+SUM(H5:H24) -> 77760 | I25: =+SUM(I5:I24) -> 207340 | J25: =+SUM(J5:J24) -> 268046 | K25: =+SUM(K5:K24) -> 2467786 | L25: =+SUM(L5:L24) -> 4000 | M25: =+SUM(M5:M24) -> 160000 | ... S25: =+SUM(S5:S24) -> 1833062
N26: =+'Faculty '!O38 -> 735552 | O26: =+'Faculty '!P38 -> 1029771
N27: =+N25+N26 -> 927016 | O27: =+O25+O26 -> 1297817
R29: APPROVED /NOT APPROVED
B34: PREPARED BY | G34: VERIFIED BY | L34: VERIFIED BY
B35: (Y RAMA RAO) | G35: (Ch KALIKA DEVI) | L35: ( SATYANARAYAN MOHANTY) | R35: (SHRI.RAM PHAL DWIVEDI)
B36: Jr SUPERINTENDENT | G36: =+'Faculty '!G50 -> ASSISTANT REGISTRAR (F&A) | L36: DEPUTY REGISTRAR | R36: REGISTRAR
A62: 7 | B62: NT1026 | C62: Mr.Sachidananda Rath (Joined on 21.05.2026) | D62: Assistant Registrar | E62: Level-10 | F62: =ROUND(56100*11/31,0) -> 19906 | G62: =ROUND(F62*60%,0) -> 11944 | H62: =ROUND(3600*160%*11/31,0) -> 2044 | I62: =ROUND(F62*20/100,0) -> 3981 | J62: =ROUND(SUM(F62+G62)*0.14,0) -> 4459 | K62: =SUM(F62:J62) -> 42334 | L62: 200 | M62: 0 | N62: =ROUND(SUM(F62+G62)*0.1,0) -> 3185 | O62: =+J62 -> 4459 | P62: 650 | Q62: 0 | R62: =SUM(L62:Q62) -> 8494 | S62: =+K62-R62 -> 33840

Sheet Director salary
A2: Salary Statement of Prof. Shalivahan, Director - IIPE for the month of August'2026 | C2: Level -17
A3: Particulars | B3: Amount (Rs.)
A4: Basic | B4: 225000
A5: DA @ 60% of Basic | B5: =+B4*60/100 -> 135000
A6: Gross salary | B6: =+B4+B5 -> 360000
A7: Deductions
A8: 1.Towards Car usage | B8: 700
A9: 2.TDS | B9: 90000
A10: 3.Professional Tax | B10: 200
A11: 4.Group Insurance | B11: 0
A12: 5.CGHS Contribution | B12: 1000
A13: 6. Medical expenses recovery | B13: 0
A14: 7.Other Deductions | B14: 0
A15: 7.Amount Payable to IIT(ISM) Dhanbad
A16: a.LIC Premium | B16: 9521
A17: b.Licence Fee | B17: 0
A18: c.General Insurance Scheme(GIS) | B18: 280
A19: 8.Sub total (a+b+c) | B19: =+SUM(B16:B18) -> 9801
A20: 9.GPF | B20: 42000
A21: Total deductions(1+2+3+4+5+6) | B21: =+SUM(B8:B14)+B20+B19 -> 143701
A22: Net Salary Payable | B22: =+B6-B21 -> 216299
A24: Note: 1.An amount of Rs. 9,801/-( as per Sl No.8) is to be transferred to IIT(ISM) Dhanbad A/c. No. 37052696309
A25: 2.An amount of Rs. 42,000/-( as per Sl No.9) is to be transferred to IIT(ISM) Dhanbad A/c. No. 30018377022
A31: PREPARED BY | B31: VERIFIED BY
A32: (Y RAMA RAO) | B32: (Ch KALIKA DEVI)
A33: Jr SUPTD | B33: =+Staff!G36 -> ASSISTANT REGISTRAR (F&A)
A38: VERIFIED BY
A39: ( SATYANARAYAN MOHANTY)
A40: DEPUTY REGISTRAR
A44: APPROVED/NOT APPROVED
A49: (SHRI.RAM PHAL DWIVEDI)
A50: REGISTRAR

Sheet Arrears
A1: Joining time pay for the period 25.02.2023 to 26.02.2023 in respect of Shri Ramphal Dwivedi - Registrar
A3: Particulars | B3: Amount
A4: Basic pay - Rs.151400/- | B4: =ROUND(151400*2/28,0) -> 10814
A5: DA@ 42% | B5: =ROUND(B4*42/100,0) -> 4542
A6: HRA @ 18% | B6: =ROUND(B4*18/100,0) -> 1947
A7: TA | B7: 0
A8: NPS Employer share | B8: =+ROUND(SUM(B4:B5)*14/100,0) -> 2150
A9: Gross salary | B9: =+SUM(B4:B8) -> 19453
A10: Less:
A11: NPS Employer share | B11: =+B8 -> 2150
A12: NPS Employee share | B12: =+ROUND(SUM(B4:B5)*10/100,0) -> 1536
A13: Net amount payable | B13: =+B9-B11-B12 -> 15767
A20: PREPARED BY | B20: VERIFIED BY
A21: Y RAMARAO | B21: (CH KALIKADEVI)
A22: JUNIOR SUPERINTENDENT | B22: ASSISTANT REGISTRAR
A27: VERIFIED BY
A28: ( DR.B.MURALI KRISHNA)
A29: JOINT REGISTRAR
A33: APPROVED/NOT APPROVED
A38: (SHRI.RAM PHAL DWIVEDI)
A39: REGISTRAR

Sheet PV Narayana Rao
A1: Statement of salary of Shri P V Narayana Rao As per the office order no. IIPE/Estb/Pay-Fixation/NTS1024 Dt: 31.10.2025
A2: Month | B2: Basic Pay | C2: Basic for allowances | D2: Incremental Basic | E2: DA @ 58% | F2: HRA 20 % | G2: TA | H2: NPS Employer Share | I2: Gross Salary | J2: Less:NPS Employee Share | K2: NPS Employee share | L2: Professional Tax | M2: CGHS | N2: Net amount payable
A3: 45901 | B3: 26833 | C3: =ROUND(151400*7/30,0) -> 35327 | D3: =+C3-B3 -> 8494 | E3: =ROUND(D3*58/100,0) -> 4927 | F3: =ROUND(D3*20/100,0) -> 1699 | G3: =ROUND(3600*3/100*7/30,0) -> 25 | H3: =+E3*0.14 -> 689.78 | I3: =+SUM(E3:H3) -> 7340.78 | J3: =+E3*0.1 -> 492.7 | K3: =+H3 -> 689.78 | L3: 0 | N3: =+I3-J3-K3 -> 6158.3
A4: DA Arrears | B4: 26833 | C4: 0 | D4: 0 | E4: =ROUND(B4*3/100,0) -> 805 | F4: 0 | G4: 0 | H4: =+SUM(D4:E4)*0.14 -> 112.7 | I4: =+E4+F4+H4 -> 917.7 | J4: =+SUM(D4:E4)*0.1 -> 80.5 | K4: =+H4 -> 112.7 | L4: 0 | N4: =+I4-J4-K4 -> 724.5
A5: 45931 | B5: 115000 | C5: 151400 | D5: 151400 | E5: =ROUND(D5*58/100,0) -> 87812 | F5: =ROUND(D5*20/100,0) -> 30280 | G5: =3600*158/100 -> 5688 | H5: =+SUM(B5+E5)*0.14 -> 28393.68 | I5: =+SUM(E5:H5)+B5 -> 267173.68 | J5: =+SUM(B5+E5)*0.1 -> 20281.2 | K5: =+H5 -> 28393.68 | L5: 200 | M5: 1000 | N5: =+I5-J5-K5-L5-M5 -> 217298.8
N9: =+SUM(N3:N5) -> 224181.6
A10: Indian Institute of Petroleum and Energy (IIPE)
A11: Statement of Salary of Shri P. V. Narayana Rao
A12: As per Office Order No. IIPE/Estb/Pay-Fixation/NTS1024 dated 31.10.2025
A13: Particulars | B13: September'2025 (for 7 Days) | C13: DA Arrears | D13: October'2025
A14: Basic Pay | B14: 26833 | C14: 26833 | D14: 115000
A15: Basic for Allowances | B15: 35327 | C15: 0 | D15: 151400
A16: Incremental Basic | B16: 8494 | C16: 0 | D16: 151400
A17: DA @ 58% | B17: 4927 | C17: 805 | D17: 87812
A18: HRA @ 20% | B18: 1699 | C18: 0 | D18: 30280
A19: TA (Transport Allowance) | B19: 25 | C19: 0 | D19: 5688
A20: NPS Employer Share | B20: 690 | C20: 113 | D20: 28394
A21: Gross Salary | B21: 7341 | C21: 918 | D21: 267174
A22: Less: NPS Employee Share | B22: 493 | C22: 81 | D22: 20281
A23: Professional Tax | B23: – | C23: – | D23: 200
A24: CGHS | B24: – | C24: – | D24: 1000
A25: Net Amount Payable | B25: 6158 | C25: 725 | D25: 217299
A27: Total Amount Payable | B27: =+B25+C25+D25 -> 224182
A30: PREPARED BY | D30: VERIFIED BY
A31: (Y RAMARAO) | D31: (CH KALIKADEVI)
A32: JUNIOR SUPERINTENDENT | D32: ASSISTANT REGISTRAR
A37: VERIFIED BY
A38: ( DR.B.MURALI KRISHNA)
A39: JOINT REGISTRAR
A43: APPROVED/NOT APPROVED
A48: (SHRI.RAM PHAL DWIVEDI)
A49: REGISTRAR

Sheet SE Salary 
A1: Salary Statement of Shri.P.V.Narayana Rao, Superintendent Engineer - IIPE for the month of October'2025
A2: Particulars | B2: Amount (Rs.)
A3: Basic | B3: 115000
A4: DA @ 58% of Basic | B4: =+B3*58/100 -> 66700
A5: HRA | B5: =+ROUND(B3*0.2,0) -> 23000
A6: TA | B6: =3600*1.58 -> 5688
A7: NPS Employer share | B7: =+ROUND(SUM(B3:B4)*0.14,0) -> 25438
A8: Gross salary | B8: =+SUM(B3:B7) -> 235826
A9: Deductions
A10: TDS | B10: 0
A11: Professional Tax | B11: 200
A12: CGHS Contribution | B12: 1000
A13: Medical expenses recovery | B13: 0
A14: NPS Employer share | B14: =+B7 -> 25438
A15: NPS Employee share | B15: =+ROUND(SUM(B3:B4)*0.1,0) -> 18170
A16: Total Deductiosns (a+b+c+d+e+f) | B16: =+SUM(B10:B15) -> 44808
A17: Net Salary Payable | B17: =+B8-B16 -> 191018
A22: JS:
A27: AR:
A32: RG:

Sheet Staff (2)
A2: Salary Statement of Non Teaching Staff for the month of February' 2023 (Attendance from 26.01.2023 to 25.02.2023)
A3: S.No. | B3: Name of the Employee | C3: Designation | D3: Department | E3: Date of Joining | F3: Pay Scale | G3: Basic | H3: DA 38 % | I3: TA | J3: HRA 18 % | K3: Monthly salary | L3: No.of days payable | M3: Gross salary | N3: PT | O3: TDS | P3: NPS | Q3: Group Insurance | R3: Other Recovery | S3: Total Deductions | T3: Net Salary
A4: 1 | B4: Shri.Ram Phal Dwivedi | G4: =ROUNDUP(167200*2/28,0) -> 11943 | H4: =ROUND(G4*38%,0) -> 4538 | I4: 0 | J4: =ROUND(G4*18/100,0) -> 2150 | K4: =SUM(G4:J4) -> 18631 | L4: 2 | M4: =+K4 -> 18631 | N4: 150 | O4: 10000 | P4: 0 | Q4: 0 | R4: 0 | S4: =SUM(N4:R4) -> 10150 | T4: =+M4-S4 -> 8481
A5: 2 | B5: Dr. B Murali Krishna | C5: Dy. Registrar | D5: Admn | E5: 43643 | F5: Level-12 | G5: =+ROUNDUP(96900*0.928571428571429,0) -> 89979 | H5: =ROUND(G5*38%,0) -> 34192 | I5: 0 | J5: =ROUND(G5*18/100,0) -> 16196 | K5: =SUM(G5:J5) -> 140367 | L5: 26 | M5: =+K5 -> 140367 | N5: 200 | O5: 20000 | P5: =ROUND(SUM(G5+H5)*10%*26/28,0) -> 11530 | Q5: 495 | R5: 3000 | S5: =SUM(N5:R5) -> 35225 | T5: =+M5-S5 -> 105142 | V5: 96900
A6: 3 | B6: Dr. B Murali Krishna | G6: =+ROUND(88700*0.0714285714285714,0) -> 6336 | H6: =ROUND(G6*38%,0) -> 2408 | I6: =+ROUND(4968*0.0714285714285714,0) -> 355 | J6: =ROUND(G6*18/100,0) -> 1140 | K6: =SUM(G6:J6) -> 10239 | L6: 2 | M6: =+K6 -> 10239 | P6: =+(88700+33706)*0.0714285714285714*0.1 -> 874.32857 | Q6: 0 | R6: 0 | S6: =SUM(N6:R6) -> 874.32857 | T6: =+M6-P6 -> 9364.6714
A7: 4 | B7: Mr.Jitender Kumar | G7: 82200 | H7: =ROUND(G7*38%,0) -> 31236 | I7: =3600*138% -> 4968 | J7: =ROUND(G7*18/100,0) -> 14796 | K7: =SUM(G7:J7) -> 133200 | L7: 28 | M7: =+K7*L7/28 -> 133200 | N7: 200 | O7: 21100 | P7: =ROUND(SUM(G7+H7)*10%,0) -> 11344 | Q7: 495 | R7: 0 | S7: =SUM(N7:R7) -> 33139 | T7: =+M7-S7 -> 100061
A8: 5 | B8: Mr. T Venkata Ravi Krishna | G8: 69700 | H8: =ROUND(G8*38%,0) -> 26486 | I8: =3600*138% -> 4968 | J8: =ROUND(G8*18/100,0) -> 12546 | K8: =SUM(G8:J8) -> 113700 | L8: 28 | M8: =+K8*L8/28 -> 113700 | N8: 200 | O8: 12200 | P8: =ROUND(SUM(G8+H8)*10%,0) -> 9619 | Q8: 495 | R8: 0 | S8: =SUM(N8:R8) -> 22514 | T8: =+M8-S8 -> 91186
A9: 6 | B9: Mr. Genius Sanjog | G9: 69700 | H9: =ROUND(G9*38%,0) -> 26486 | I9: =3600*138% -> 4968 | J9: =ROUND(G9*18/100,0) -> 12546 | K9: =SUM(G9:J9) -> 113700 | L9: 28 | M9: =+K9*L9/28 -> 113700 | N9: 200 | O9: 14500 | P9: =ROUND(SUM(G9+H9)*10%,0) -> 9619 | Q9: 495 | R9: 0 | S9: =SUM(N9:R9) -> 24814 | T9: =+M9-S9 -> 88886
A10: 7 | B10: Mr. K Rama Krishna | C10: O S | D10: Admn | E10: 43682 | F10: Level-7 | G10: 49000 | H10: =ROUND(G10*38%,0) -> 18620 | I10: =1800*138% -> 2484 | J10: =ROUND(G10*18/100,0) -> 8820 | K10: =SUM(G10:J10) -> 78924 | L10: 28 | M10: =+K10*L10/28 -> 78924 | N10: 200 | O10: 4000 | P10: =ROUND(SUM(G10+H10)*10%,0) -> 6762 | Q10: 297 | R10: 0 | S10: =SUM(N10:R10) -> 11259 | T10: =+M10-S10 -> 67665
A11: 8 | B11: Mrs. S Naga Venkata Saritha | C11: P S to Director | D11: Admn | E11: 43699 | F11: Level-7 | G11: 49000 | H11: =ROUND(G11*38%,0) -> 18620 | I11: 0 | J11: =ROUND(G11*18/100,0) -> 8820 | K11: =SUM(G11:J11) -> 76440 | L11: 28 | M11: =+K11*L11/28 -> 76440 | N11: 200 | O11: 5700 | P11: =ROUND(SUM(G11+H11)*10%,0) -> 6762 | Q11: 297 | R11: 3206 | S11: =SUM(N11:R11) -> 16165 | T11: =+M11-S11 -> 60275 | V11: Smt.SNV Saritha
A12: 9 | B12: Mrs. Ch Kalika Devi | C12: F O | D12: Admn | E12: 43712 | F12: Level-7 | G12: 49000 | H12: =ROUND(G12*38%,0) -> 18620 | I12: =1800*138% -> 2484 | J12: =ROUND(G12*18/100,0) -> 8820 | K12: =SUM(G12:J12) -> 78924 | L12: 28 | M12: =+K12*L12/28 -> 78924 | N12: 200 | O12: 1000 | P12: =ROUND(SUM(G12+H12)*10%,0) -> 6762 | Q12: 297 | R12: 0 | S12: =SUM(N12:R12) -> 8259 | T12: =+M12-S12 -> 70665
A13: 10 | B13: Mr. Y Rama Rao | E13: 43850 | F13: Level-5 | G13: 31900 | H13: =ROUND(G13*38%,0) -> 12122 | I13: =1800*138% -> 2484 | J13: =ROUND(G13*18/100,0) -> 5742 | K13: =SUM(G13:J13) -> 52248 | L13: 28 | M13: =+K13*L13/28 -> 52248 | N13: 200 | O13: 0 | P13: =ROUND(SUM(G13+H13)*10%,0) -> 4402 | Q13: 198 | R13: 0 | S13: =SUM(N13:R13) -> 4800 | T13: =+M13-S13 -> 47448
A14: 11 | B14: Mr. G. Shiva Kumar | E14: 43859 | F14: Level-6 | G14: 38700 | H14: =ROUND(G14*38%,0) -> 14706 | I14: =1800*138% -> 2484 | J14: =ROUND(G14*18/100,0) -> 6966 | K14: =SUM(G14:J14) -> 62856 | L14: 28 | M14: =+K14*L14/28 -> 62856 | N14: 200 | O14: 0 | P14: =ROUND(SUM(G14+H14)*10%,0) -> 5341 | Q14: 297 | R14: 0 | S14: =SUM(N14:R14) -> 5838 | T14: =+M14-S14 -> 57018
A15: 12 | B15: Mr.K Nagesh | E15: 43837 | F15: Level-6 | G15: 38700 | H15: =ROUND(G15*38%,0) -> 14706 | I15: =1800*138% -> 2484 | J15: =ROUND(G15*18/100,0) -> 6966 | K15: =SUM(G15:J15) -> 62856 | L15: 28 | M15: =+K15*L15/28 -> 62856 | N15: 200 | O15: 0 | P15: =ROUND(SUM(G15+H15)*10%,0) -> 5341 | Q15: 297 | R15: 0 | S15: =SUM(N15:R15) -> 5838 | T15: =+M15-S15 -> 57018
A16: 13 | B16: Mr.U. Rambabu | G16: 22400 | H16: =ROUND(G16*38%,0) -> 8512 | I16: =1800*138% -> 2484 | J16: =ROUND(G16*18/100,0) -> 4032 | K16: =SUM(G16:J16) -> 37428 | L16: 28 | M16: =+K16*L16/28 -> 37428 | N16: 200 | O16: 0 | P16: =ROUND(SUM(G16+H16)*10%,0) -> 3091 | Q16: 198 | R16: 0 | S16: =SUM(N16:R16) -> 3489 | T16: =+M16-S16 -> 33939
A17: 14 | B17: Mr.Appala Murthy N | G17: 22400 | H17: =ROUND(G17*38%,0) -> 8512 | I17: =1800*138% -> 2484 | J17: =ROUND(G17*18/100,0) -> 4032 | K17: =SUM(G17:J17) -> 37428 | L17: 28 | M17: =+K17*L17/28 -> 37428 | N17: 200 | O17: 0 | P17: =ROUND(SUM(G17+H17)*10%,0) -> 3091 | Q17: 198 | R17: 0 | S17: =SUM(N17:R17) -> 3489 | T17: =+M17-S17 -> 33939
A18: 15 | B18: Mr.Somesh Katta | G18: 22400 | H18: =ROUND(G18*38%,0) -> 8512 | I18: =1800*138% -> 2484 | J18: =ROUND(G18*18/100,0) -> 4032 | K18: =SUM(G18:J18) -> 37428 | L18: 28 | M18: =+K18*L18/28 -> 37428 | N18: 200 | O18: 0 | P18: =ROUND(SUM(G18+H18)*10%,0) -> 3091 | Q18: 198 | R18: 0 | S18: =SUM(N18:R18) -> 3489 | T18: =+M18-S18 -> 33939
A19: 16 | B19: Mr.Surendra Ratnala | G19: 22400 | H19: =ROUND(G19*38%,0) -> 8512 | I19: =1800*138% -> 2484 | J19: =ROUND(G19*18/100,0) -> 4032 | K19: =SUM(G19:J19) -> 37428 | L19: 28 | M19: =+K19*L19/28 -> 37428 | N19: 200 | O19: 0 | P19: =ROUND(SUM(G19+H19)*10%,0) -> 3091 | Q19: 198 | S19: =SUM(N19:R19) -> 3489 | T19: =+M19-S19 -> 33939
A20: 17 | B20: Mr.Satyaprasad Yerra | G20: 22400 | H20: =ROUND(G20*38%,0) -> 8512 | I20: =1800*138% -> 2484 | J20: =ROUND(G20*18/100,0) -> 4032 | K20: =SUM(G20:J20) -> 37428 | L20: 28 | M20: =+K20*L20/28 -> 37428 | N20: 200 | O20: 0 | P20: =ROUND(SUM(G20+H20)*10%,0) -> 3091 | Q20: 198 | R20: 0 | S20: =SUM(N20:R20) -> 3489 | T20: =+M20-S20 -> 33939
A21: 18 | B21: Mr.Nulu Praveen Kumar | G21: 22400 | H21: =ROUND(G21*38%,0) -> 8512 | I21: =1800*138% -> 2484 | J21: =ROUND(G21*18/100,0) -> 4032 | K21: =SUM(G21:J21) -> 37428 | L21: 28 | M21: =+K21*L21/28 -> 37428 | N21: 200 | O21: 0 | P21: =ROUND(SUM(G21+H21)*10%,0) -> 3091 | Q21: 198 | R21: 0 | S21: =SUM(N21:R21) -> 3489 | T21: =+M21-S21 -> 33939
A22: 19 | B22: Mr.Satanjee Pandey | G22: 22400 | H22: =ROUND(G22*38%,0) -> 8512 | I22: =1800*138% -> 2484 | J22: =ROUND(G22*18/100,0) -> 4032 | K22: =SUM(G22:J22) -> 37428 | L22: 28 | M22: =+K22*L22/28 -> 37428 | N22: 200 | O22: 0 | P22: =ROUND(SUM(G22+H22)*10%,0) -> 3091 | Q22: 198 | R22: 0 | S22: =SUM(N22:R22) -> 3489 | T22: =+M22-S22 -> 33939
A23: 20 | B23: Mr.Goru Lakshmi Papa Rao | G23: 22400 | H23: =ROUND(G23*38%,0) -> 8512 | I23: =1800*138% -> 2484 | J23: =ROUND(G23*18/100,0) -> 4032 | K23: =SUM(G23:J23) -> 37428 | L23: 28 | M23: =+K23*L23/28 -> 37428 | N23: 200 | O23: 0 | P23: =ROUND(SUM(G23+H23)*10%,0) -> 3091 | Q23: 198 | R23: 0 | S23: =SUM(N23:R23) -> 3489 | T23: =+M23-S23 -> 33939
A24: 21 | B24: Mr.Bidyadhoro Majhi | G24: 22400 | H24: =ROUND(G24*38%,0) -> 8512 | I24: =1800*138% -> 2484 | J24: =ROUND(G24*18/100,0) -> 4032 | K24: =SUM(G24:J24) -> 37428 | L24: 28 | M24: =+K24*L24/28 -> 37428 | N24: 200 | O24: 0 | P24: =ROUND(SUM(G24+H24)*10%,0) -> 3091 | Q24: 198 | R24: 0 | S24: =SUM(N24:R24) -> 3489 | T24: =+M24-S24 -> 33939
A25: 22 | B25: Mr.Mithun Babu Nallana | G25: 22400 | H25: =ROUND(G25*38%,0) -> 8512 | I25: =1800*138% -> 2484 | J25: =ROUND(G25*18/100,0) -> 4032 | K25: =SUM(G25:J25) -> 37428 | L25: 28 | M25: =+K25*L25/28 -> 37428 | N25: 200 | O25: 0 | P25: =ROUND(SUM(G25+H25)*10%,0) -> 3091 | Q25: 198 | R25: 0 | S25: =SUM(N25:R25) -> 3489 | T25: =+M25-S25 -> 33939
A26: 23 | B26: Mr.Etteneni Nikhil Kumar | G26: 22400 | H26: =ROUND(G26*38%,0) -> 8512 | I26: =1800*138% -> 2484 | J26: =ROUND(G26*18/100,0) -> 4032 | K26: =SUM(G26:J26) -> 37428 | L26: 28 | M26: =+K26*L26/28 -> 37428 | N26: 200 | O26: 0 | P26: =ROUND(SUM(G26+H26)*10%,0) -> 3091 | Q26: 198 | R26: 0 | S26: =SUM(N26:R26) -> 3489 | T26: =+M26-S26 -> 33939
A27: Total | G27: =+SUM(G4:G26) -> 832558 | H27: =+SUM(H4:H26) -> 316372 | I27: =+SUM(I4:I26) -> 55003 | J27: =+SUM(J4:J26) -> 149860 | K27: =+SUM(K4:K26) -> 1353793 | M27: =+SUM(M4:M26) -> 1353793 | N27: =+SUM(N4:N26) -> 4350 | O27: =+SUM(O4:O26) -> 88500 | P27: =+SUM(P4:P26) -> 112357.33 | Q27: =+SUM(Q4:Q26) -> 5841 | R27: =+SUM(R4:R26) -> 6206 | S27: =+SUM(S4:S26) -> 217254.33 | T27: =+SUM(T4:T26) -> 1136538.7
A34: PREPARED BY | C34: CHECKED BY | F34: CHECKED BY | H34: CHECKED BY | M34: VERIFIED | R34: APPROVED BY
A35: ( Y RAMA RAO) | C35: ( CH KALIKADEVI) | F35: ( K RAMA KRISHNA) | H35: ( K RAMA KRISHNA) | M35: ( DR.B.MURALI KRISHNA) | R35: (SHRI.RAM PHAL DWIVEDI)
A36: ACCOUNTANT | C36: SUPERINTENDENT (Acts) | F36: SUPERINTENDENT - OFFICE | H36: SUPERINTENDENT - OFFICE | M36: Dy.REGISTRAR | R36: REGISTRAR
A68: * With Reference to IIPE Office orders IIPE/Adm/126 Dated 01.12.2020 , IIPE/Adm/103 Dated:25.08.2022 & IIPE/Estb/122(iii) Dated: 24.01.2023, on implementation of officiating pay, the applicable basic pay is Rs.96,900/-.

Sheet NPS rough 
A1: NPS Calculation
A2: Name of the Employee | B2: Basic | C2: DA | D2: Employee | E2: Employer
A3: Dr. Somnath Ghosh | B3: 131400 | C3: =ROUND(B3*38%,0) -> 49932 | D3: =+SUM(B3:C3)*10/100 -> 18133.2 | E3: =+D3*14/10 -> 25386.48
A4: Dr. Deepak Amban Mishra | B4: 131400 | C4: =ROUND(B4*38%,0) -> 49932 | D4: =+SUM(B4:C4)*10/100 -> 18133.2 | E4: =+D4*14/10 -> 25386.48
A5: Dr. Randhi Ramunaidu | B5: 131400 | C5: =ROUND(B5*38%,0) -> 49932 | D5: =+SUM(B5:C5)*10/100 -> 18133.2 | E5: =+D5*14/10 -> 25386.48
A6: Dr. Arun Kumar Pujari | B6: 131400 | C6: =ROUND(B6*38%,0) -> 49932 | D6: =+SUM(B6:C6)*10/100 -> 18133.2 | E6: =+D6*14/10 -> 25386.48
A7: Dr. C.Veerabhadra Rao | B7: 131400 | C7: =ROUND(B7*38%,0) -> 49932 | D7: =+SUM(B7:C7)*10/100 -> 18133.2 | E7: =+D7*14/10 -> 25386.48
A8: Dr. Chanchayya Gupta Ch | B8: 131400 | C8: =ROUND(B8*38%,0) -> 49932 | D8: =+SUM(B8:C8)*10/100 -> 18133.2 | E8: =+D8*14/10 -> 25386.48
A9: Dr. Geddada Nagesh | B9: 131400 | C9: =ROUND(B9*38%,0) -> 49932 | D9: =+SUM(B9:C9)*10/100 -> 18133.2 | E9: =+D9*14/10 -> 25386.48
A10: Dr. P Aparoy | B10: 131400 | C10: =ROUND(B10*38%,0) -> 49932 | D10: =+SUM(B10:C10)*10/100 -> 18133.2 | E10: =+D10*14/10 -> 25386.48
A11: Dr. Rajat Jain | B11: 131400 | C11: =ROUND(B11*38%,0) -> 49932 | D11: =+SUM(B11:C11)*10/100 -> 18133.2 | E11: =+D11*14/10 -> 25386.48
A12: Dr. Ranjan Pramanik | B12: 131400 | C12: =ROUND(B12*38%,0) -> 49932 | D12: =+SUM(B12:C12)*10/100 -> 18133.2 | E12: =+D12*14/10 -> 25386.48
A13: Dr. P. Venkata Reddy | B13: 110800 | C13: =ROUND(B13*38%,0) -> 42104 | D13: =+SUM(B13:C13)*10/100 -> 15290.4 | E13: =+D13*14/10 -> 21406.56
A14: Dr. Kakati Himangshu | B14: 110800 | C14: =ROUND(B14*38%,0) -> 42104 | D14: =+SUM(B14:C14)*10/100 -> 15290.4 | E14: =+D14*14/10 -> 21406.56
... A50: Mr.Etteneni Nikhil Kumar | B50: 22400 | C50: =ROUND(B50*38%,0) -> 8512 | D50: =+SUM(B50:C50)*10/100 -> 3091.2 | E50: =+D50*14/10 -> 4327.68
A51: Grand Total per Month | B51: =+SUM(B3:B50) -> 3872600 | C51: =+SUM(C3:C50) -> 1471588 | D51: =+SUM(D3:D50) -> 534418.8 | E51: =+SUM(E3:E50) -> 748186.32
A52: Grand Total upto February'2023(11Months) | D52: =+D51*11 -> 5878606.8 | E52: =+E51*11 -> 8230049.5
A53: Grand Total upto March '2023(12Months) | D53: =+D51*12 -> 6413025.6 | E53: =+E51*12 -> 8978235.8

Sheet NPS rough  (2)
A1: NPS Calculation
A2: Name of the Employee | B2: Basic | C2: DA | D2: Employee | E2: Employer
A3: Dr. Somnath Ghosh | B3: 131400 | C3: =ROUND(B3*38%,0) -> 49932 | D3: =+SUM(B3:C3)*10/100 -> 18133.2 | E3: =+D3*14/10 -> 25386.48
A4: Dr. Deepak Amban Mishra | B4: 131400 | C4: =ROUND(B4*38%,0) -> 49932 | D4: =+SUM(B4:C4)*10/100 -> 18133.2 | E4: =+D4*14/10 -> 25386.48
A5: Dr. Randhi Ramunaidu | B5: 131400 | C5: =ROUND(B5*38%,0) -> 49932 | D5: =+SUM(B5:C5)*10/100 -> 18133.2 | E5: =+D5*14/10 -> 25386.48
A6: Dr. Arun Kumar Pujari | B6: 131400 | C6: =ROUND(B6*38%,0) -> 49932 | D6: =+SUM(B6:C6)*10/100 -> 18133.2 | E6: =+D6*14/10 -> 25386.48
A7: Dr. C.Veerabhadra Rao | B7: 131400 | C7: =ROUND(B7*38%,0) -> 49932 | D7: =+SUM(B7:C7)*10/100 -> 18133.2 | E7: =+D7*14/10 -> 25386.48
A8: Dr. Chanchayya Gupta Ch | B8: 131400 | C8: =ROUND(B8*38%,0) -> 49932 | D8: =+SUM(B8:C8)*10/100 -> 18133.2 | E8: =+D8*14/10 -> 25386.48
A9: Dr. Geddada Nagesh | B9: 131400 | C9: =ROUND(B9*38%,0) -> 49932 | D9: =+SUM(B9:C9)*10/100 -> 18133.2 | E9: =+D9*14/10 -> 25386.48
A10: Dr. P Aparoy | B10: 131400 | C10: =ROUND(B10*38%,0) -> 49932 | D10: =+SUM(B10:C10)*10/100 -> 18133.2 | E10: =+D10*14/10 -> 25386.48
A11: Dr. Rajat Jain | B11: 131400 | C11: =ROUND(B11*38%,0) -> 49932 | D11: =+SUM(B11:C11)*10/100 -> 18133.2 | E11: =+D11*14/10 -> 25386.48
A12: Dr. Ranjan Pramanik | B12: 131400 | C12: =ROUND(B12*38%,0) -> 49932 | D12: =+SUM(B12:C12)*10/100 -> 18133.2 | E12: =+D12*14/10 -> 25386.48
A13: Dr. P. Venkata Reddy | B13: 110800 | C13: =ROUND(B13*38%,0) -> 42104 | D13: =+SUM(B13:C13)*10/100 -> 15290.4 | E13: =+D13*14/10 -> 21406.56
A14: Dr. Kakati Himangshu | B14: 110800 | C14: =ROUND(B14*38%,0) -> 42104 | D14: =+SUM(B14:C14)*10/100 -> 15290.4 | E14: =+D14*14/10 -> 21406.56
... A29: Dr.Sharon H | B29: 89900 | C29: =ROUND(B29*38%,0) -> 34162 | D29: =+SUM(B29:C29)*10/100 -> 12406.2 | E29: =+D29*14/10 -> 17368.68
A30: Grand Total | B30: =+SUM(B3:B29) -> 3051400 | C30: =+SUM(C3:C29) -> 1159532 | D30: =+SUM(D3:D29) -> 421093.2 | E30: =+SUM(E3:E29) -> 589530.48
A31: Dr. B Murali Krishna | B31: 96900 | C31: =ROUND(B31*38%,0) -> 36822 | D31: =+SUM(B31:C31)*10/100 -> 13372.2 | E31: =+D31*14/10 -> 18721.08
A32: Mr.Jitender Kumar | B32: 82200 | C32: =ROUND(B32*38%,0) -> 31236 | D32: =+SUM(B32:C32)*10/100 -> 11343.6 | E32: =+D32*14/10 -> 15881.04
A33: Mr. T Venkata Ravi Krishna | B33: 69700 | C33: =ROUND(B33*38%,0) -> 26486 | D33: =+SUM(B33:C33)*10/100 -> 9618.6 | E33: =+D33*14/10 -> 13466.04
A34: Mr. Genius Sanjog | B34: 69700 | C34: =ROUND(B34*38%,0) -> 26486 | D34: =+SUM(B34:C34)*10/100 -> 9618.6 | E34: =+D34*14/10 -> 13466.04
A35: Mr. K Rama Krishna | B35: 49000 | C35: =ROUND(B35*38%,0) -> 18620 | D35: =+SUM(B35:C35)*10/100 -> 6762 | E35: =+D35*14/10 -> 9466.8
A36: Mrs. S Naga Venkata Saritha | B36: 49000 | C36: =ROUND(B36*38%,0) -> 18620 | D36: =+SUM(B36:C36)*10/100 -> 6762 | E36: =+D36*14/10 -> 9466.8
A37: Mrs. Ch Kalika Devi | B37: 49000 | C37: =ROUND(B37*38%,0) -> 18620 | D37: =+SUM(B37:C37)*10/100 -> 6762 | E37: =+D37*14/10 -> 9466.8
A38: Mr. Y Rama Rao | B38: 31900 | C38: =ROUND(B38*38%,0) -> 12122 | D38: =+SUM(B38:C38)*10/100 -> 4402.2 | E38: =+D38*14/10 -> 6163.08
A39: Mr. G. Shiva Kumar | B39: 38700 | C39: =ROUND(B39*38%,0) -> 14706 | D39: =+SUM(B39:C39)*10/100 -> 5340.6 | E39: =+D39*14/10 -> 7476.84
A40: Mr.K Nagesh | B40: 38700 | C40: =ROUND(B40*38%,0) -> 14706 | D40: =+SUM(B40:C40)*10/100 -> 5340.6 | E40: =+D40*14/10 -> 7476.84
A41: Mr.U. Rambabu | B41: 22400 | C41: =ROUND(B41*38%,0) -> 8512 | D41: =+SUM(B41:C41)*10/100 -> 3091.2 | E41: =+D41*14/10 -> 4327.68
A42: Mr.Appala Murthy N | B42: 22400 | C42: =ROUND(B42*38%,0) -> 8512 | D42: =+SUM(B42:C42)*10/100 -> 3091.2 | E42: =+D42*14/10 -> 4327.68
... A51: Mr.Etteneni Nikhil Kumar | B51: 22400 | C51: =ROUND(B51*38%,0) -> 8512 | D51: =+SUM(B51:C51)*10/100 -> 3091.2 | E51: =+D51*14/10 -> 4327.68
A52: Grand Total per Month | B52: =+SUM(B31:B51) -> 821200 | C52: =+SUM(C31:C51) -> 312056 | D52: =+SUM(D31:D51) -> 113325.6 | E52: =+SUM(E31:E51) -> 158655.84
A55: Particulars | B55: Basic | C55: DA | D55: Employee (10%) | E55: Employer(14%)
A56: Faculty ( 27 No's) | B56: 3051400 | C56: =+B56*38/100 -> 1159532 | D56: =+SUM(B56:C56)*10/100 -> 421093.2 | E56: =+D56*14/10 -> 589530.48
A57: Staff ( 21 No's) | B57: 821200 | C57: =+B57*38/100 -> 312056 | D57: =+SUM(B57:C57)*10/100 -> 113325.6 | E57: =+D57*14/10 -> 158655.84
A58: Per Month | D58: =+D56+D57 -> 534418.8 | E58: =+E56+E57 -> 748186.32
A59: Upto February'2023 | E59: =+E58*11 -> 8230049.5
A60: Upto March'2023 | E60: =+E58*12 -> 8978235.8
A75: Particulars | B75: Basic | C75: DA | D75: Employee (10%) | E75: Employer(14%)
A76: Faculty ( 27 No's) | B76: 3051400 | C76: =+B76*38/100 -> 1159532 | D76: =+SUM(B76:C76)*10/100 -> 421093.2 | E76: =+D76*14/10 -> 589530.48
A77: Staff ( 21 No's) | B77: 821200 | C77: =+B77*38/100 -> 312056 | D77: =+SUM(B77:C77)*10/100 -> 113325.6 | E77: =+D77*14/10 -> 158655.84
A78: Per Month | D78: =+D76+D77 -> 534418.8 | E78: =+E76+E77 -> 748186.32
...
